Workbook

Sheet Read Me
A1: Hamilton United 2010 Boys OPDL — Week-by-Week Plan 2026/27
A2: Coach Gianfranco Mirto · Nov 2, 2026 → Oct 31, 2027 · 52 weeks
A4: Tabs
A5: Year Plan | B5: One row per week: phase, theme, moments, the core principles trained, weekly objective and what each training day looks like.
A6: Principles | B6: The 23 core principles from the game model chart: when each is installed, how many weeks train it, and the first week (formulas).
A7: Sessions | B7: The example key session for every week (Wednesday, MD-3): objective, learning intentions, success criteria, and a 90-minute plan.
A8: Week Template | B8: The training week: what each day is for, its space, numbers and load.
A9: Summary | B9: Weeks per phase and monthly planned load (formulas), with a load chart.
A11: How to edit | B11: Blue cells on Year Plan (Volume, Intensity) are planning inputs: change them and the Summary updates. Edit any session text freely.
A12: Example row | B12: Week 1 (Nov 2) shows the format: one “Find ways to…” objective, a key session on the Sessions tab, and short Tue/Thu companions.
A14: Sources | B14: Nov–Apr themes, objectives and session objectives 1–7: coach’s Google Doc “Session Objectives” (6-Month Tactical Periodization).
B15: Game model (1-3-4-3, moments, principles): coach’s Game Model Part 1 & 2. May–Oct blocks: drafted to extend the plan; review before use.
A16: Assumptions | B16: 4 sessions × 90 min (Mon, Tue, Wed, Thu); Saturday game; Friday and Sunday off.
B17: OPDL competition dates, the mid-season break (two weeks from Jul 19) and the season end are placeholders: confirm against the OPDL fixture list.
B18: Load: planned relative values, 1 = low, 5 = high; 0 = rest week. Planning targets only. Track real load with session RPE × minutes.
B19: Holiday weeks: Dec 21 optional programme, Dec 28 off.
B20: Pitch sizes in yards. Success criteria are coaching targets for the session, not measured statistics.
A22: Moments | B22: AO attacking organization
B23: AT attacking transition
B24: DO defensive organization
B25: DT defensive transition

Sheet Year Plan
A1: Year Plan — week by week
A2: Key session each week = Wednesday (MD-3), detailed on the Sessions tab. Amber rows = competition phase.
A4: Wk | B4: Week of (Mon) | C4: Month | D4: Phase | E4: Theme | F4: Moments | G4: Session obj. # | H4: Core principles trained | I4: Weekly objective | J4: Mon · MD+2 Recover | K4: Tue · MD-4 Strength | L4: Wed · MD-3 Endurance (key) | M4: Thu · MD-2 Speed | N4: Sat · Game | O4: Physical focus | P4: Volume (1–5) | Q4: Intensity (1–5) | R4: Notes / checkpoints
A5: 1 | B5: 46328 | C5: Nov | D5: Development 1 | E5: Create solutions | F5: AO + DO | G5: 3, 6 | H5: AO Purpose · AO Width/depth · AO Support | I5: Find ways to create passing options around, through and beyond the opposition. | J5: Technical: rondos, passing patterns, 1v1 moves; intro to the week’s problem | K5: 5v5 + 2 neutrals (25x20 yd), 4 x 4 min: defending team protects a central gate | L5: KEY SESSION · Passing options: width, depth, support (see Sessions tab) | M5: 1v1 and 2v1 to goal, 6–8 s reps, full recovery; finishing both feet | N5: Winter game or internal scrimmage (confirm) | O5: Movement quality, strength base | P5: 3 | Q5: 2 | R5: Baseline week: film the Saturday game for the November baseline
A6: 2 | B6: 46335 | C6: Nov | D6: Development 1 | E6: Create solutions | F6: AO + DO | G6: 3, 6 | H6: AO Overloads · AO Support · AO Purpose | I6: Find ways to create and exploit numerical advantages to progress the ball forward. | J6: Technical: rondos, passing patterns, 1v1 moves; intro to the week’s problem | K6: 4v4 + 4 bumpers (30x25 yd): play through the bumpers to switch the point of attack | L6: KEY SESSION · The +1 at the back (see Sessions tab) | M6: Speed: 10–20 yd sprints with a ball, then finishing from cut-backs | N6: Winter game or internal scrimmage (confirm) | O6: Movement quality, strength base | P6: 3 | Q6: 2
A7: 3 | B7: 46342 | C7: Nov | D7: Development 1 | E7: Create solutions | F7: AO + DO | G7: 2, 3 | H7: AO Play through/around/over · AO Width/depth | I7: Find ways to progress the ball by recognizing when to play through, around or over the opposition. | J7: Technical: rondos, passing patterns, 1v1 moves; intro to the week’s problem | K7: 6v6 compact block (35x30 yd): defenders deny central gates; attackers look for gaps | L7: KEY SESSION · Through, around or over (see Sessions tab) | M7: Transition: 3v2 counter waves, 8-second limit to shoot | N7: Winter game or internal scrimmage (confirm) | O7: Movement quality, strength base | P7: 3 | Q7: 2
A8: 4 | B8: 46349 | C8: Nov | D8: Development 1 | E8: Create solutions | F8: DO | G8: 6 | H8: DO Compact | I8: Find ways to prevent the opposition from progressing through central areas. | J8: Technical: rondos, passing patterns, 1v1 moves; intro to the week’s problem | K8: 4v4 + GKs (25x20 yd): press-cover-balance, 90-s bouts | L8: KEY SESSION · Protect the centre (see Sessions tab) | M8: Recovery runs: lose the ball, sprint back inside; 5 reps x 3 | N8: Winter game or internal scrimmage (confirm) | O8: Movement quality, strength base | P8: 3 | Q8: 2
A9: 5 | B9: 46356 | C9: Nov | D9: Development 1 | E9: Create solutions | F9: AO + DO | G9: 3, 6 | H9: AO Purpose · AO Support · DO Compact | I9: Find ways to create passing options and defend forward through compactness and pressure. | J9: Technical: rondos, passing patterns, 1v1 moves; intro to the week’s problem | K9: 5v5 + 2 neutrals: defending team protects the middle | L9: KEY SESSION · Consolidate: where do I help the team? (see Sessions tab) | M9: Speed: reaction starts + 1v1 duels; first look at making play predictable (force wide) | N9: Winter game or internal scrimmage (confirm) | O9: Movement quality, strength base | P9: 3 | Q9: 2 | R9: Block review at month end: compare with baseline
A10: 6 | B10: 46363 | C10: Dec | D10: Development 1 | E10: Break lines | F10: AO | G10: 2 | H10: AO Combinations · AO Runners in front & behind | I10: Find ways to break lines through purposeful movement and combination play. | J10: Technical: rondos, passing patterns, 1v1 moves; intro to the week’s problem | K10: 5v5 + 2 inside neutrals (30x25 yd): neutrals must receive between the lines | L10: KEY SESSION · Third-man combinations (see Sessions tab) | M10: Finishing from third-man runs; speed off the shoulder | N10: Winter game or internal scrimmage (confirm) | O10: Strength, aerobic base | P10: 3.5 | Q10: 2.5
A11: 7 | B11: 46370 | C11: Dec | D11: Development 1 | E11: Break lines | F11: AO + DO | G11: 2, 3 | H11: AO Manipulate · AO Runners in front & behind · DO Make play predictable | I11: Find ways to create space by manipulating the opposition’s defensive structure. | J11: Technical: rondos, passing patterns, 1v1 moves; intro to the week’s problem | K11: DO: 6v6 with trap zones; press on triggers (back pass, poor touch, ball to a fullback) | L11: KEY SESSION · Manipulate to create space (see Sessions tab) | M11: Short sprints + finishing; light load before the holidays | N11: Winter game or internal scrimmage (confirm) | O11: Strength, aerobic base | P11: 3.5 | Q11: 2.5 | R11: Block review: Development 1
A12: 8 | B12: 46377 | C12: Dec | D12: Development 1 | E12: Holiday | F12: — | G12: — | H12: — | I12: Optional: individual programme and futsal. | J12: — | K12: — | L12: — | M12: — | N12: No game | O12: Strength, aerobic base | P12: 1 | Q12: 1 | R12: Lighter week: individual programme sent home
A13: 9 | B13: 46384 | C13: Dec | D13: Development 1 | E13: Holiday | F13: — | G13: — | H13: — | I13: Rest. | J13: — | K13: — | L13: — | M13: — | N13: No game | O13: Strength, aerobic base | P13: 0 | Q13: 0 | R13: Full rest
A14: 10 | B14: 46391 | C14: Jan | D14: Development 2 | E14: Win it back | F14: DO | G14: 6 | H14: DO Press · DO Step forward · DO Win high | I14: Find ways to regain possession by coordinating pressure around the ball. | J14: Technical: rondos, passing patterns, 1v1 moves; intro to the week’s problem | K14: 4v4 duels (25x20 yd), 1-min bouts: aggressive contact on the receiver | L14: KEY SESSION · Press, cover, balance (see Sessions tab) | M14: Speed and agility: COD drills, 5–10 yd reaction sprints | N14: Winter game or internal scrimmage (confirm) | O14: Speed, agility | P14: 3.5 | Q14: 3
A15: 11 | B15: 46398 | C15: Jan | D15: Development 2 | E15: Win it back | F15: DT | G15: 7 | H15: DT React & repress · DT Contact · DT Deny | I15: Find ways to immediately regain possession following a loss of the ball. | J15: Technical: rondos, passing patterns, 1v1 moves; intro to the week’s problem | K15: 3v3 transition boxes, 45-s bouts | L15: KEY SESSION · React and repress (see Sessions tab) | M15: Repeat sprints: transition runs, 6 x 20 yd | N15: Winter game or internal scrimmage (confirm) | O15: Speed, agility | P15: 3.5 | Q15: 3
A16: 12 | B16: 46405 | C16: Jan | D16: Development 2 | E16: Win it back | F16: DO | G16: 6 | H16: DO Make play predictable · DO Press · DO Win high | I16: Find ways to force the opposition into predictable areas to regain possession. | J16: Technical: rondos, passing patterns, 1v1 moves; intro to the week’s problem | K16: 5v5: force inside game (central trap) | L16: KEY SESSION · Make play predictable (see Sessions tab) | M16: Agility + finishing after regains | N16: Winter game or internal scrimmage (confirm) | O16: Speed, agility | P16: 3.5 | Q16: 3
A17: 13 | B17: 46412 | C17: Jan | D17: Development 2 | E17: Win it back | F17: DT + DO | G17: 7 | H17: DT Recover shape · DT Deny · DO Protect | I17: Find ways to delay the opposition’s attack and protect the space behind. | J17: Technical: rondos, passing patterns, 1v1 moves; intro to the week’s problem | K17: 4v4 + recovering player | L17: KEY SESSION · Delay and protect behind (see Sessions tab) | M17: Speed: recovery sprints inside, 5 x 30 yd | N17: Winter game or internal scrimmage (confirm) | O17: Speed, agility | P17: 3.5 | Q17: 3
A18: 14 | B18: 46419 | C18: Feb | D18: Development 2 | E18: Connect the moments | F18: All 4 | G18: 5, 7 | H18: AO Purpose · AO Overloads · DT React & repress | I18: Find ways to connect building with an immediate reaction when we lose the ball. | J18: Technical: rondos, passing patterns, 1v1 moves; intro to the week’s problem | K18: 5v5 + 2 with switching roles | L18: KEY SESSION · Build → Lose → Repress (see Sessions tab) | M18: Power: jumps + short sprints; transition finishing | N18: Winter game or internal scrimmage (confirm) | O18: Power, repeat sprints | P18: 3.5 | Q18: 3.5
A19: 15 | B19: 46426 | C19: Feb | D19: Development 2 | E19: Connect the moments | F19: All 4 | G19: 5, 6 | H19: DO Press · AT Forward · AT Exploit | I19: Find ways to win the ball and attack before the opposition reorganizes. | J19: Technical: rondos, passing patterns, 1v1 moves; intro to the week’s problem | K19: 4v4 + 2 counter targets | L19: KEY SESSION · Defend → Win → Counter (see Sessions tab) | M19: Power: 10 yd accelerations + finishing | N19: Winter game or internal scrimmage (confirm) | O19: Power, repeat sprints | P19: 3.5 | Q19: 3.5 | R19: Checkpoint: mid-year IDP meetings
A20: 16 | B20: 46433 | C20: Feb | D20: Development 2 | E20: Connect the moments | F20: All 4 | G20: 4, 7 | H20: AO Runners in front & behind · AO Combinations · DT Recover shape | I20: Find ways to finish attacks while protecting against the counter. | J20: Technical: rondos, passing patterns, 1v1 moves; intro to the week’s problem | K20: 6v6 two-goal game | L20: KEY SESSION · Progress → Final action → Defend the transition (see Sessions tab) | M20: Repeat sprints 6 x 30 yd | N20: Winter game or internal scrimmage (confirm) | O20: Power, repeat sprints | P20: 3.5 | Q20: 3.5
A21: 17 | B21: 46440 | C21: Feb | D21: Development 2 | E21: Connect the moments | F21: All 4 | G21: 5, 6 | H21: DO Step forward · DO Win high · AT Forward | I21: Find ways to regain the ball high and turn it into a goal. | J21: Technical: rondos, passing patterns, 1v1 moves; intro to the week’s problem | K21: 5v5 press boxes | L21: KEY SESSION · Press → Regain → Attack (see Sessions tab) | M21: Power + finishing | N21: Winter game or internal scrimmage (confirm) | O21: Power, repeat sprints | P21: 3.5 | Q21: 3.5
A22: 18 | B22: 46447 | C22: Mar | D22: Pre-competition | E22: Attack the moment | F22: AT | G22: 5 | H22: AT Forward · AT Exploit · AT Support | I22: Find ways to exploit numerical advantages immediately after winning possession. | J22: Recovery + technical: rondos, passing patterns, short video review | K22: 4v4 transition boxes | L22: KEY SESSION · Exploit the numbers after a regain (see Sessions tab) | M22: Sprint + finish; pre-season volume | N22: Pre-season friendly | O22: Pre-season volume peak | P22: 4.5 | Q22: 3.5 | R22: Pre-season begins
A23: 19 | B23: 46454 | C23: Mar | D23: Pre-competition | E23: Attack the moment | F23: AT | G23: 5 | H23: AT Forward · AT Space · AT Support · AT Secure | I23: Find ways to progress forward quickly before the opposition can reorganize, and to secure possession when the attack is not on. | J23: Recovery + technical: rondos, passing patterns, short video review | K23: 5v5 + 2: switch on the regain | L23: KEY SESSION · Go now, or secure (see Sessions tab) | M23: Speed endurance 8 x 40 yd | N23: Pre-season friendly | O23: Pre-season volume peak | P23: 4.5 | Q23: 3.5
A24: 20 | B24: 46461 | C24: Mar | D24: Pre-competition | E24: Attack the moment | F24: AO | G24: 1 | H24: AO Runners in front & behind · AT Space | I24: Find ways to create final actions by getting behind the opposition’s back line. | J24: Recovery + technical: rondos, passing patterns, short video review | K24: 4v4 + 2 end-zone runners | L24: KEY SESSION · Get behind the back line (see Sessions tab) | M24: Speed off the mark + finishing 1v1 with the GK | N24: Pre-season friendly | O24: Pre-season volume peak | P24: 4.5 | Q24: 3.5
A25: 21 | B25: 46468 | C25: Mar | D25: Pre-competition | E25: Attack the moment | F25: AO | G25: 4 | H25: AO Runners in front & behind · AO Width/depth | I25: Find ways to attack the box with purposeful movements and coordinated runs. | J25: Recovery + technical: rondos, passing patterns, short video review | K25: 5v5 + wide players | L25: KEY SESSION · Attack the box (see Sessions tab) | M25: Finishing volume | N25: Pre-season friendly | O25: Pre-season volume peak | P25: 4.5 | Q25: 3.5
A26: 22 | B26: 46475 | C26: Mar | D26: Pre-competition | E26: Attack the moment | F26: AO | G26: 4 | H26: AO Combinations · AO Support | I26: Find ways to create finishing opportunities through quick combinations around the box. | J26: Recovery + technical: rondos, passing patterns, short video review | K26: 4v4 + 2 wall players | L26: KEY SESSION · Combine around the box (see Sessions tab) | M26: Finishing under fatigue | N26: Pre-season friendly | O26: Pre-season volume peak | P26: 4.5 | Q26: 3.5
A27: 23 | B27: 46482 | C27: Apr | D27: Pre-competition | E27: Execute our identity | F27: All 4 | G27: 1–7 | H27: AO Purpose · AT Secure · DO Compact · DT React & repress | I27: Find ways to execute all four moments against different problems. | J27: Recovery + technical: rondos, passing patterns, short video review | K27: 6v6 all-moments game | L27: KEY SESSION · Moment switching (see Sessions tab) | M27: Taper: short and sharp | N27: Pre-season friendly | O27: Taper to game speed | P27: 3.5 | Q27: 4
A28: 24 | B28: 46489 | C28: Apr | D28: Pre-competition | E28: Execute our identity | F28: AO | G28: 2, 3 | H28: AO Overloads · AO Play through/around/over · AO Purpose | I28: Find ways to beat a high press with the 1-3-2 build. | J28: Recovery + technical: rondos, passing patterns, short video review | K28: 5v5 press-resistance | L28: KEY SESSION · Beat a high press (see Sessions tab) | M28: Speed + set-piece introduction | N28: Pre-season friendly | O28: Taper to game speed | P28: 3.5 | Q28: 4
A29: 25 | B29: 46496 | C29: Apr | D29: Pre-competition | E29: Execute our identity | F29: AO | G29: 2, 4 | H29: AO Manipulate · AO Width/depth · AO Combinations | I29: Find ways to create chances against a low block. | J29: Recovery + technical: rondos, passing patterns, short video review | K29: 6v6 + 4 wide players | L29: KEY SESSION · Break a low block (see Sessions tab) | M29: Finishing from cut-backs | N29: Pre-season friendly | O29: Taper to game speed | P29: 3.5 | Q29: 4
A30: 26 | B30: 46503 | C30: Apr | D30: Pre-competition | E30: Execute our identity | F30: All 4 + set pieces | G30: 1–7 | H30: Set pieces · AO Purpose | I30: Find ways to bring the whole game model into match conditions. | J30: Recovery + technical: rondos, passing patterns, short video review | K30: Light 6v6 | L30: KEY SESSION · Game rehearsal (see Sessions tab) | M30: Activation + set pieces | N30: Pre-season friendly | O30: Taper to game speed | P30: 3.5 | Q30: 4 | R30: Checkpoint: pre-season review before the league
A31: 27 | B31: 46510 | C31: May | D31: Competition 1 | E31: Compete with identity | F31: AO | G31: 2 | H31: AO Play through/around/over · AO Overloads | I31: Find ways to progress against different pressing shapes. | J31: Recovery: mobility, rondos 5v2 / 4v2, 10-min video review of Saturday (60–75 min) | K31: 5v5 press boxes | L31: KEY SESSION · Beat their press (see Sessions tab) | M31: Speed + set pieces: attacking corners | N31: OPDL league game | O31: Maintain through the week | P31: 3 | Q31: 4.5 | R31: League starts (confirm date)
A32: 28 | B32: 46517 | C32: May | D32: Competition 1 | E32: Compete with identity | F32: AO | G32: 4 | H32: AO Runners in front & behind · AO Width/depth | I32: Find ways to attack the box with coordinated runs. | J32: Recovery: mobility, rondos 5v2 / 4v2, 10-min video review of Saturday (60–75 min) | K32: 5v5 + wide players | L32: KEY SESSION · Attack the box (see Sessions tab) | M32: Finishing + set pieces: free kicks | N32: OPDL league game | O32: Maintain through the week | P32: 3 | Q32: 4.5
A33: 29 | B33: 46524 | C33: May | D33: Competition 1 | E33: Compete with identity | F33: Set pieces | G33: — | H33: Set pieces | I33: Find ways to create chances from attacking corners. | J33: Recovery: mobility, rondos 5v2 / 4v2, 10-min video review of Saturday (60–75 min) | K33: 6v6 + set-piece restarts | L33: KEY SESSION · Attacking corners (see Sessions tab) | M33: Speed + corner rehearsal | N33: OPDL league game | O33: Maintain through the week | P33: 3 | Q33: 4.5
A34: 30 | B34: 46531 | C34: May | D34: Competition 1 | E34: Compete with identity | F34: Set pieces | G34: — | H34: Set pieces | I34: Find ways to defend corners and free kicks with a zonal/man hybrid. | J34: Recovery: mobility, rondos 5v2 / 4v2, 10-min video review of Saturday (60–75 min) | K34: 6v6 | L34: KEY SESSION · Defending set pieces (see Sessions tab) | M34: Speed + defending set pieces | N34: OPDL league game | O34: Maintain through the week | P34: 3 | Q34: 4.5
A35: 31 | B35: 46538 | C35: May | D35: Competition 1 | E35: Compete with identity | F35: AO | G35: 2 | H35: AO Combinations · AO Manipulate | I35: Find ways to break lines against a mid block. | J35: Recovery: mobility, rondos 5v2 / 4v2, 10-min video review of Saturday (60–75 min) | K35: 5v5 + 2 inside neutrals | L35: KEY SESSION · Progress against a mid block (see Sessions tab) | M35: Speed + set pieces | N35: OPDL league game | O35: Maintain through the week | P35: 3 | Q35: 4.5
A36: 32 | B36: 46545 | C36: Jun | D36: Competition 1 | E36: Compete with identity | F36: AT | G36: 5 | H36: AT Forward · AT Exploit · AT Space · AT Secure | I36: Find ways to create goal-scoring opportunities within the first few actions after regaining possession. | J36: Recovery: mobility, rondos 5v2 / 4v2, 10-min video review of Saturday (60–75 min) | K36: 4v4 transitions | L36: KEY SESSION · Counter after the regain (see Sessions tab) | M36: Speed + set pieces | N36: OPDL league game | O36: Maintain through the week | P36: 3 | Q36: 4.5
A37: 33 | B37: 46552 | C37: Jun | D37: Competition 1 | E37: Compete with identity | F37: DO | G37: 6 | H37: DO Compact · DO Protect · DO Step forward · DO Win high | I37: Find ways to defend forward through compactness and pressure. | J37: Recovery: mobility, rondos 5v2 / 4v2, 10-min video review of Saturday (60–75 min) | K37: 4v4 press | L37: KEY SESSION · Protect the centre, win high (see Sessions tab) | M37: Speed + set pieces | N37: OPDL league game | O37: Maintain through the week | P37: 3 | Q37: 4.5
A38: 34 | B38: 46559 | C38: Jun | D38: Competition 1 | E38: Compete with identity | F38: DT | G38: 7 | H38: DT React & repress · DT Contact · DT Deny | I38: Find ways to immediately regain possession following a loss of the ball. | J38: Recovery: mobility, rondos 5v2 / 4v2, 10-min video review of Saturday (60–75 min) | K38: 3v3 boxes | L38: KEY SESSION · Repress (see Sessions tab) | M38: Speed + set pieces | N38: OPDL league game | O38: Maintain through the week | P38: 3 | Q38: 4.5
A39: 35 | B39: 46566 | C39: Jun | D39: Competition 1 | E39: Compete with identity | F39: AO | G39: 4 | H39: AO Combinations · AO Support | I39: Find ways to create scoring opportunities through combination play in the final third. | J39: Recovery: mobility, rondos 5v2 / 4v2, 10-min video review of Saturday (60–75 min) | K39: 4v4 + wall players | L39: KEY SESSION · Final-third combinations (see Sessions tab) | M39: Speed + set pieces | N39: OPDL league game | O39: Maintain through the week | P39: 3 | Q39: 4.5 | R39: Checkpoint: end-of-June review
A40: 36 | B40: 46573 | C40: Jul | D40: Competition 2 | E40: Adapt the plan | F40: AO + DO | G40: 2, 6 | H40: AO Width/depth · AO Support · DO Compact | I40: Find ways to apply our principles in the 1-4-2-3-1. | J40: Recovery: mobility, rondos 5v2 / 4v2, 10-min video review of Saturday (60–75 min) | K40: 6v6 | L40: KEY SESSION · Introduce the 1-4-2-3-1 (see Sessions tab) | M40: Speed + set pieces | N40: OPDL league game | O40: Maintain; then rest | P40: 2.5 | Q40: 4
A41: 37 | B41: 46580 | C41: Jul | D41: Competition 2 | E41: Adapt the plan | F41: AO + DO | G41: 2, 6 | H41: AO Manipulate · DO Make play predictable | I41: Find ways to switch shape during a game. | J41: Recovery: mobility, rondos 5v2 / 4v2, 10-min video review of Saturday (60–75 min) | K41: 5v5 | L41: KEY SESSION · Flip the triangle (see Sessions tab) | M41: Speed + set pieces | N41: OPDL league game | O41: Maintain; then rest | P41: 2.5 | Q41: 4
...

Sheet Principles
A1: Core principles — coverage across the year
A2: The 23 principles from the game model chart. Weeks trained and first week are formulas on the Year Plan’s “Core principles trained” column.
A4: Moment | B4: Principle | C4: Tag (as used on Year Plan) | D4: What it means | E4: Installed (month) | F4: Weeks trained | G4: First week trained | H4: First week of (Mon)
A5: AO | B5: Purpose | C5: AO Purpose | D5: Possession with purpose | E5: Nov | F5: =COUNTIF('Year Plan'!$H$5:$H$56,"*"&C5&"*") -> 9 | G5: =IFERROR(_xlfn.MINIFS('Year Plan'!$A$5:$A$56,'Year Plan'!$H$5:$H$56,"*"&C5&"*"),"") -> 1 | H5: =IFERROR(INDEX('Year Plan'!$B$5:$B$56,MATCH(G5,'Year Plan'!$A$5:$A$56,0)),"") -> 46328
A6: AO | B6: Overloads | C6: AO Overloads | D6: Create & exploit overloads | E6: Nov | F6: =COUNTIF('Year Plan'!$H$5:$H$56,"*"&C6&"*") -> 5 | G6: =IFERROR(_xlfn.MINIFS('Year Plan'!$A$5:$A$56,'Year Plan'!$H$5:$H$56,"*"&C6&"*"),"") -> 2 | H6: =IFERROR(INDEX('Year Plan'!$B$5:$B$56,MATCH(G6,'Year Plan'!$A$5:$A$56,0)),"") -> 46335
A7: AO | B7: Play through/around/over | C7: AO Play through/around/over | D7: Play through, around, or over | E7: Nov | F7: =COUNTIF('Year Plan'!$H$5:$H$56,"*"&C7&"*") -> 4 | G7: =IFERROR(_xlfn.MINIFS('Year Plan'!$A$5:$A$56,'Year Plan'!$H$5:$H$56,"*"&C7&"*"),"") -> 3 | H7: =IFERROR(INDEX('Year Plan'!$B$5:$B$56,MATCH(G7,'Year Plan'!$A$5:$A$56,0)),"") -> 46342
A8: AO | B8: Width/depth | C8: AO Width/depth | D8: Maintain width & depth | E8: Nov | F8: =COUNTIF('Year Plan'!$H$5:$H$56,"*"&C8&"*") -> 7 | G8: =IFERROR(_xlfn.MINIFS('Year Plan'!$A$5:$A$56,'Year Plan'!$H$5:$H$56,"*"&C8&"*"),"") -> 1 | H8: =IFERROR(INDEX('Year Plan'!$B$5:$B$56,MATCH(G8,'Year Plan'!$A$5:$A$56,0)),"") -> 46328
A9: AO | B9: Runners in front & behind | C9: AO Runners in front & behind | D9: Make runs to receive or attack in behind | E9: Dec | F9: =COUNTIF('Year Plan'!$H$5:$H$56,"*"&C9&"*") -> 9 | G9: =IFERROR(_xlfn.MINIFS('Year Plan'!$A$5:$A$56,'Year Plan'!$H$5:$H$56,"*"&C9&"*"),"") -> 6 | H9: =IFERROR(INDEX('Year Plan'!$B$5:$B$56,MATCH(G9,'Year Plan'!$A$5:$A$56,0)),"") -> 46363
A10: AO | B10: Support | C10: AO Support | D10: Support & passing options | E10: Nov | F10: =COUNTIF('Year Plan'!$H$5:$H$56,"*"&C10&"*") -> 6 | G10: =IFERROR(_xlfn.MINIFS('Year Plan'!$A$5:$A$56,'Year Plan'!$H$5:$H$56,"*"&C10&"*"),"") -> 1 | H10: =IFERROR(INDEX('Year Plan'!$B$5:$B$56,MATCH(G10,'Year Plan'!$A$5:$A$56,0)),"") -> 46328
A11: AO | B11: Combinations | C11: AO Combinations | D11: Third-man combinations | E11: Dec | F11: =COUNTIF('Year Plan'!$H$5:$H$56,"*"&C11&"*") -> 8 | G11: =IFERROR(_xlfn.MINIFS('Year Plan'!$A$5:$A$56,'Year Plan'!$H$5:$H$56,"*"&C11&"*"),"") -> 6 | H11: =IFERROR(INDEX('Year Plan'!$B$5:$B$56,MATCH(G11,'Year Plan'!$A$5:$A$56,0)),"") -> 46363
A12: AO | B12: Manipulate | C12: AO Manipulate | D12: Play across the game channel to move opposition players and create space | E12: Dec | F12: =COUNTIF('Year Plan'!$H$5:$H$56,"*"&C12&"*") -> 5 | G12: =IFERROR(_xlfn.MINIFS('Year Plan'!$A$5:$A$56,'Year Plan'!$H$5:$H$56,"*"&C12&"*"),"") -> 7 | H12: =IFERROR(INDEX('Year Plan'!$B$5:$B$56,MATCH(G12,'Year Plan'!$A$5:$A$56,0)),"") -> 46370
A13: AT | B13: Forward | C13: AT Forward | D13: First look forward | E13: Mar | F13: =COUNTIF('Year Plan'!$H$5:$H$56,"*"&C13&"*") -> 6 | G13: =IFERROR(_xlfn.MINIFS('Year Plan'!$A$5:$A$56,'Year Plan'!$H$5:$H$56,"*"&C13&"*"),"") -> 15 | H13: =IFERROR(INDEX('Year Plan'!$B$5:$B$56,MATCH(G13,'Year Plan'!$A$5:$A$56,0)),"") -> 46426
A14: AT | B14: Exploit | C14: AT Exploit | D14: Attack disorganization quickly | E14: Mar | F14: =COUNTIF('Year Plan'!$H$5:$H$56,"*"&C14&"*") -> 4 | G14: =IFERROR(_xlfn.MINIFS('Year Plan'!$A$5:$A$56,'Year Plan'!$H$5:$H$56,"*"&C14&"*"),"") -> 15 | H14: =IFERROR(INDEX('Year Plan'!$B$5:$B$56,MATCH(G14,'Year Plan'!$A$5:$A$56,0)),"") -> 46426
A15: AT | B15: Support | C15: AT Support | D15: Support the attack | E15: Mar | F15: =COUNTIF('Year Plan'!$H$5:$H$56,"*"&C15&"*") -> 4 | G15: =IFERROR(_xlfn.MINIFS('Year Plan'!$A$5:$A$56,'Year Plan'!$H$5:$H$56,"*"&C15&"*"),"") -> 18 | H15: =IFERROR(INDEX('Year Plan'!$B$5:$B$56,MATCH(G15,'Year Plan'!$A$5:$A$56,0)),"") -> 46447
A16: AT | B16: Space | C16: AT Space | D16: Exploit open space | E16: Mar | F16: =COUNTIF('Year Plan'!$H$5:$H$56,"*"&C16&"*") -> 4 | G16: =IFERROR(_xlfn.MINIFS('Year Plan'!$A$5:$A$56,'Year Plan'!$H$5:$H$56,"*"&C16&"*"),"") -> 19 | H16: =IFERROR(INDEX('Year Plan'!$B$5:$B$56,MATCH(G16,'Year Plan'!$A$5:$A$56,0)),"") -> 46454
... A27: DT | B27: Recover shape | C27: DT Recover shape | D27: Recover shape quickly if unable to win the ball | E27: Jan | F27: =COUNTIF('Year Plan'!$H$5:$H$56,"*"&C27&"*") -> 4 | G27: =IFERROR(_xlfn.MINIFS('Year Plan'!$A$5:$A$56,'Year Plan'!$H$5:$H$56,"*"&C27&"*"),"") -> 13 | H27: =IFERROR(INDEX('Year Plan'!$B$5:$B$56,MATCH(G27,'Year Plan'!$A$5:$A$56,0)),"") -> 46412
B29: Principles never trained | F29: =COUNTIF(F5:F27,0) -> 0
A30: Installed month = when the principle is first taught as the main focus (periodization deck, slide 8). Earlier weeks may preview it, e.g. counters in February before AT is installed in March.

Sheet Sessions
A1: Sessions — the example key session for each week (Wednesday, MD-3, 90 min)
A2: Structure: Objective → Learning intentions → Success criteria · Activation 15′ · Part 1 25′ (small-sided) · Part 2 25′ (expanded) · Game 20′ · Review 5′
A4: Wk | B4: Week of | C4: Theme | D4: Session title | E4: Core principles | F4: Session objective | G4: Learning intentions | H4: Success criteria | I4: Activation (15′) | J4: Part 1 · small-sided (25′) | K4: Part 2 · expanded (25′) | L4: Game (20′) | M4: Coaching question (review 5′)
A5: 1 | B5: 46328 | C5: Create solutions | D5: Passing options: width, depth, support | E5: AO Purpose · AO Width/depth · AO Support | F5: Find ways to create passing options around, through and beyond the opposition. | G5: Take width and depth early · Offer an angle to the ball carrier · Scan before receiving | H5: Ball carrier has 3 options (left, right, ahead) · Receivers open body to play forward | I5: Rondos 4v1 → 5v2 (10x10 yd), 2 touch, scan before receiving | J5: Positional game 6v6 + 3 floaters (40x35 yd): score by passing into an end-zone player. Wide players must stay in the wide channels. | K5: GK + 3 CBs + two 6s vs 4 pressers (half field): build in a 1-3-2 and score by passing into either of 2 mini-goals at halfway | L5: 11v11 (or 9v9): a goal that started from a GK build-out counts double | M5: Where is the free player? Can I give the ball carrier another option?
A6: 2 | B6: 46335 | C6: Create solutions | D6: The +1 at the back | E6: AO Overloads · AO Support · AO Purpose | F6: Find ways to create and exploit numerical advantages to progress the ball forward. | G6: Find the +1 · Attract pressure before releasing · Play to the free player | H6: Ball reaches the middle third with a free player facing forward 3+ times per block | I6: Rondo 4v2 + 1 middle player (12x12 yd): split pass through the middle = 2 points | J6: Zones game: 3v2 in zone 1 → 4v3 in zone 2 (3 zones across 50x35 yd). Progress only by creating the overload. | K6: 1-3-2 build vs 1-3 front press + 3 counter-attackers: GK must be involved before the ball crosses zone 1 | L6: 11v11: every restart from our GK | M6: Where is the numerical advantage? Who is the +1?
A7: 3 | B7: 46342 | C7: Create solutions | D7: Through, around or over | E7: AO Play through/around/over · AO Width/depth | F7: Find ways to progress the ball by recognizing when to play through, around or over the opposition. | G7: Read the press · Through when the central lane is open · Around when they’re compact · Over when space is behind | H7: Players choose the right option on 2 of every 3 progressions (coach tally) | I7: Passing triangles with a third-man release, both feet | J7: 3-option game 7v7 + GKs (50x40 yd): central gate goal = through (3 pts), wide channel entry = around (2 pts), long ball to a target = over (1 pt) | K7: 11 vs 8 build-out: coach changes the press (high / mid / low) and players must read it and pick the route | L7: 11v11 conditioned: name the route (through, around, over) on each entry | M7: If we can’t play through, can we go around or over?
A8: 4 | B8: 46349 | C8: Create solutions | D8: Protect the centre | E8: DO Compact | F8: Find ways to prevent the opposition from progressing through central areas. | G8: Stay compact centrally · Shift together, ball side · Keep short distances between lines | H8: Opponents get fewer than 3 central entries per 5-min block | I8: Shadow shape: 1-5-2-3 shifting to the coach’s ball, then 1-5-4-1 | J8: 6v6 + GKs with 2 central gates: defenders win points by forcing play wide | K8: 8v10 half field: we defend in the 1-5-2-3, regain and counter to 2 mini-goals | L8: 11v11: points for regaining the ball in the middle third | M8: Where is the danger? Is the space behind me protected?
A9: 5 | B9: 46356 | C9: Create solutions | D9: Consolidate: where do I help the team? | E9: AO Purpose · AO Support · DO Compact | F9: Find ways to create passing options and defend forward through compactness and pressure. | G9: Link positioning with the ball and without it · Recover quickly and reorganize around the ball | H9: Team keeps its shape in both moments for full 5-min blocks | I9: Rondo 5v2 into 4v4 + 3 transition | J9: Positional game 7v7 + 3: lose it and the team must recover compactly within 5 s | K9: Phase play 1-3-4-3 vs 1-4-4-2: build, lose, defend in shape | L9: 11v11 free: coach freezes play to check positions | M9: Where can I position myself to help the team?
A10: 6 | B10: 46363 | C10: Break lines | D10: Third-man combinations | E10: AO Combinations · AO Runners in front & behind | F10: Find ways to break lines through purposeful movement and combination play. | G10: Receive between the lines with an open body · Use the third player to break a line · Play forward quickly | H10: 3+ line-breaking passes per 5-min block | I10: Pattern play CB → 6 → 10 with poles; third-man lay-off and pass forward | J10: Lines rondo: 3 zones (4 + 4 + 4 with 2 defenders per zone). The ball must travel through the middle zone. | K10: 7v7 + GK, half field: a goal scored after a third-man combination counts double | L10: 11v11 conditioned: line-breaking pass = 1 point | M10: Can my movement free a teammate beyond the defender?
A11: 7 | B11: 46370 | C11: Break lines | D11: Manipulate to create space | E11: AO Manipulate · AO Runners in front & behind · DO Make play predictable | F11: Find ways to create space by manipulating the opposition’s defensive structure. | G11: Move away to create space for others · Switch play to unbalance · Move defenders before exploiting the space | H11: Opponents shift, then we exploit the space they leave, 3+ times per block | I11: Rondo 4v2 with a switch target on each side | J11: 5v5 + 4 outside wide players (40x30 yd): switch play to unbalance the defence before scoring in end zones | K11: 1-3-4-3 vs a 1-4-4-2 block: 10 drops, 9 pins, rotations open the half space | L11: 11v11: DO team practices making play predictable (force wide or inside) on press triggers | M11: Did we move them before we went?
A12: 8 | B12: 46377 | C12: Holiday | D12: Holiday week: optional | E12: — | F12: Optional: individual programme and futsal. | G12: — | H12: — | I12: — | J12: Optional futsal or individual ball-mastery programme | K12: — | L12: — | M12: —
A13: 10 | B13: 46391 | C13: Win it back | D13: Press, cover, balance | E13: DO Press · DO Step forward · DO Win high | F13: Find ways to regain possession by coordinating pressure around the ball. | G13: First defender pressures · Second covers · Third balances and cuts the pass | H13: Regain within 3 passes of a trigger, 3+ times per block | I13: 2v1 → 2v2 pressing angles; curved runs to show inside or outside | J13: 4v4 + 4 bumpers in small boxes: press as a unit on the trigger | K13: 1-5-2-3 high press vs a 1-4-3-3 build-out, 11 vs 9: win it high, score within 10 s | L13: 11v11: points for regains in the final third | M13: Who goes, who covers, who balances?
A14: 11 | B14: 46398 | C14: Win it back | D14: React and repress | E14: DT React & repress · DT Contact · DT Deny | F14: Find ways to immediately regain possession following a loss of the ball. | G14: React immediately · Press the ball carrier · Deny forward passes | H14: The team that loses the ball wins it back within 5 s on 50%+ of losses | I14: Rondo 5v2: the defender who wins it must win it back immediately | J14: 5v5 + 2 (30x25 yd): a regain within 5 s of losing the ball = 1 point | K14: 8v8 + GKs: repress first; if it fails, recover into a 1-5-4-1 behind a gate line | L14: 11v11: count regains within 5 s | M14: Losing the ball: is it the start of our defending?
A15: 12 | B15: 46405 | C15: Win it back | D15: Make play predictable | E15: DO Make play predictable · DO Press · DO Win high | F15: Find ways to force the opposition into predictable areas to regain possession. | G15: Curved runs to show one way · Lock the side · Trap near the touchline | H15: 2+ regains in the trap zones per block | I15: Pressing curves: 9 forces play wide; 10s jump | J15: 6v6 with wide trap zones: a regain in a trap zone = 2 points | K15: 10v10: 1-5-2-3 forces play wide and traps with the WB + 10 + 6 | L15: 11v11 conditioned on trap zones | M15: Where do we want them to go?
A16: 13 | B16: 46412 | C16: Win it back | D16: Delay and protect behind | E16: DT Recover shape · DT Deny · DO Protect | F16: Find ways to delay the opposition’s attack and protect the space behind. | G16: Nearest player delays, doesn’t dive in · Others recover inside · Back line drops to protect depth | H16: Opponents get no shots in the first 8 s after we lose it | I16: 1v1 jockeying; recovery run angles | J16: 2v3 → 3v4 recovering defenders: delay until help arrives | K16: Transition game 9v9: lose it → nearest delays, rest recover inside, back 5 holds the line | L16: 11v11: count the counter-attacks we conceded | M16: If we can’t win it, how do we protect the goal?
... A52: 51 | B52: 46678 | C52: Peak & review | D52: IDP review week | E52: — | F52: End-of-season individual development reviews. | G52: — | H52: — | I52: — | J52: Fun festival + IDP meetings | K52: — | L52: — | M52: —

Sheet Week Template
A1: Week Template — the in-season week (game on Saturday)
A2: Same tactical theme all week; the day changes space, numbers and rest, so the physical load changes with it.
A4: Day | B4: Match-day code | C4: Purpose | D4: Space & numbers | E4: Work : rest | F4: Session length | G4: Tactical content
A5: Sun | B5: MD+1 | C5: Off | D5: — | E5: — | F5: — | G5: Sleep, mobility, hydration
A6: Mon | B6: MD+2 | C6: Recover + review | D6: Rondos 5v2 / 4v2, small grids | E6: Low intensity, long rest | F6: 60–75 min | G6: Video review: name the week’s problem
A7: Tue | B7: MD-4 | C7: Strength / tension | D7: Small spaces, 4v4–6v6, many duels | E7: Short bouts (1–4 min), equal rest | F7: 90 min | G7: Sub-principles of the weekly objective
A8: Wed | B8: MD-3 | C8: Endurance (KEY SESSION) | D8: Big spaces, 8v8–11v11 | E8: Long bouts (6–10 min) | F8: 90 min | G8: Full 1-3-4-3 structure: the week’s key session
A9: Thu | B9: MD-2 | C9: Speed | D9: Short, sharp reps | E9: Max effort, full rest | F9: 75–90 min | G9: Transitions, finishing, set pieces
A10: Fri | B10: MD-1 | C10: Off | D10: — | E10: — | F10: — | G10: Fresh legs
A11: Sat | B11: MD | C11: Game | D11: 11v11 | E11: — | F11: — | G11: Test the week’s objective
A13: Sunday game: shift every day by one. Two games in a week: drop Tuesday, keep Monday recovery and Thursday speed. Off-season months: same order, lower load.

Sheet Summary
A1: Summary — phases and planned load
A2: All values are formulas on the Year Plan tab; edit Volume / Intensity there.
A4: Phase | B4: Weeks | D4: Month | E4: Avg volume | F4: Avg intensity | G4: Training weeks
A5: Development 1 | B5: =COUNTIF('Year Plan'!$D$5:$D$56,A5) -> 9 | D5: Nov | E5: =IFERROR(AVERAGEIF('Year Plan'!$C$5:$C$56,D5,'Year Plan'!$P$5:$P$56),0) -> 3 | F5: =IFERROR(AVERAGEIF('Year Plan'!$C$5:$C$56,D5,'Year Plan'!$Q$5:$Q$56),0) -> 2 | G5: =COUNTIFS('Year Plan'!$C$5:$C$56,D5,'Year Plan'!$P$5:$P$56,">0") -> 5
A6: Development 2 | B6: =COUNTIF('Year Plan'!$D$5:$D$56,A6) -> 8 | D6: Dec | E6: =IFERROR(AVERAGEIF('Year Plan'!$C$5:$C$56,D6,'Year Plan'!$P$5:$P$56),0) -> 2 | F6: =IFERROR(AVERAGEIF('Year Plan'!$C$5:$C$56,D6,'Year Plan'!$Q$5:$Q$56),0) -> 1.5 | G6: =COUNTIFS('Year Plan'!$C$5:$C$56,D6,'Year Plan'!$P$5:$P$56,">0") -> 3
A7: Pre-competition | B7: =COUNTIF('Year Plan'!$D$5:$D$56,A7) -> 9 | D7: Jan | E7: =IFERROR(AVERAGEIF('Year Plan'!$C$5:$C$56,D7,'Year Plan'!$P$5:$P$56),0) -> 3.5 | F7: =IFERROR(AVERAGEIF('Year Plan'!$C$5:$C$56,D7,'Year Plan'!$Q$5:$Q$56),0) -> 3 | G7: =COUNTIFS('Year Plan'!$C$5:$C$56,D7,'Year Plan'!$P$5:$P$56,">0") -> 4
A8: Competition 1 | B8: =COUNTIF('Year Plan'!$D$5:$D$56,A8) -> 9 | D8: Feb | E8: =IFERROR(AVERAGEIF('Year Plan'!$C$5:$C$56,D8,'Year Plan'!$P$5:$P$56),0) -> 3.5 | F8: =IFERROR(AVERAGEIF('Year Plan'!$C$5:$C$56,D8,'Year Plan'!$Q$5:$Q$56),0) -> 3.5 | G8: =COUNTIFS('Year Plan'!$C$5:$C$56,D8,'Year Plan'!$P$5:$P$56,">0") -> 4
A9: Competition 2 | B9: =COUNTIF('Year Plan'!$D$5:$D$56,A9) -> 9 | D9: Mar | E9: =IFERROR(AVERAGEIF('Year Plan'!$C$5:$C$56,D9,'Year Plan'!$P$5:$P$56),0) -> 4.5 | F9: =IFERROR(AVERAGEIF('Year Plan'!$C$5:$C$56,D9,'Year Plan'!$Q$5:$Q$56),0) -> 3.5 | G9: =COUNTIFS('Year Plan'!$C$5:$C$56,D9,'Year Plan'!$P$5:$P$56,">0") -> 5
A10: Competition 3 | B10: =COUNTIF('Year Plan'!$D$5:$D$56,A10) -> 7 | D10: Apr | E10: =IFERROR(AVERAGEIF('Year Plan'!$C$5:$C$56,D10,'Year Plan'!$P$5:$P$56),0) -> 3.5 | F10: =IFERROR(AVERAGEIF('Year Plan'!$C$5:$C$56,D10,'Year Plan'!$Q$5:$Q$56),0) -> 4 | G10: =COUNTIFS('Year Plan'!$C$5:$C$56,D10,'Year Plan'!$P$5:$P$56,">0") -> 4
A11: Transition | B11: =COUNTIF('Year Plan'!$D$5:$D$56,A11) -> 1 | D11: May | E11: =IFERROR(AVERAGEIF('Year Plan'!$C$5:$C$56,D11,'Year Plan'!$P$5:$P$56),0) -> 3 | F11: =IFERROR(AVERAGEIF('Year Plan'!$C$5:$C$56,D11,'Year Plan'!$Q$5:$Q$56),0) -> 4.5 | G11: =COUNTIFS('Year Plan'!$C$5:$C$56,D11,'Year Plan'!$P$5:$P$56,">0") -> 5
A12: Total | B12: =SUM(B5:B11) -> 52 | D12: Jun | E12: =IFERROR(AVERAGEIF('Year Plan'!$C$5:$C$56,D12,'Year Plan'!$P$5:$P$56),0) -> 3 | F12: =IFERROR(AVERAGEIF('Year Plan'!$C$5:$C$56,D12,'Year Plan'!$Q$5:$Q$56),0) -> 4.5 | G12: =COUNTIFS('Year Plan'!$C$5:$C$56,D12,'Year Plan'!$P$5:$P$56,">0") -> 4
D13: Jul | E13: =IFERROR(AVERAGEIF('Year Plan'!$C$5:$C$56,D13,'Year Plan'!$P$5:$P$56),0) -> 1.25 | F13: =IFERROR(AVERAGEIF('Year Plan'!$C$5:$C$56,D13,'Year Plan'!$Q$5:$Q$56),0) -> 2 | G13: =COUNTIFS('Year Plan'!$C$5:$C$56,D13,'Year Plan'!$P$5:$P$56,">0") -> 2
D14: Aug | E14: =IFERROR(AVERAGEIF('Year Plan'!$C$5:$C$56,D14,'Year Plan'!$P$5:$P$56),0) -> 3.5 | F14: =IFERROR(AVERAGEIF('Year Plan'!$C$5:$C$56,D14,'Year Plan'!$Q$5:$Q$56),0) -> 4 | G14: =COUNTIFS('Year Plan'!$C$5:$C$56,D14,'Year Plan'!$P$5:$P$56,">0") -> 5
D15: Sep | E15: =IFERROR(AVERAGEIF('Year Plan'!$C$5:$C$56,D15,'Year Plan'!$P$5:$P$56),0) -> 3 | F15: =IFERROR(AVERAGEIF('Year Plan'!$C$5:$C$56,D15,'Year Plan'!$Q$5:$Q$56),0) -> 4.5 | G15: =COUNTIFS('Year Plan'!$C$5:$C$56,D15,'Year Plan'!$P$5:$P$56,">0") -> 4
D16: Oct | E16: =IFERROR(AVERAGEIF('Year Plan'!$C$5:$C$56,D16,'Year Plan'!$P$5:$P$56),0) -> 1.25 | F16: =IFERROR(AVERAGEIF('Year Plan'!$C$5:$C$56,D16,'Year Plan'!$Q$5:$Q$56),0) -> 1.75 | G16: =COUNTIFS('Year Plan'!$C$5:$C$56,D16,'Year Plan'!$P$5:$P$56,">0") -> 3
D18: Monthly averages include holiday, break and rest weeks.
